Workbook

Sheet Tracker
A1: DNB Radiodiagnosis - Final Theory Revision Tracker
A2: Exam 18 Jun 2 PM. Filter by Paper/Category/Sub-category. 'Cat marks/session' = frequency from 11 real past papers (see Sources sheet) - category level, not per-topic. Set Status, then sort 'Order' ascending to revise Partial first.
A4: Paper | B4: Category | C4: Sub-category | D4: Topic | E4: My Completeness Score (out of 10) | F4: HY | G4: Cat marks/session | H4: Freq tier | I4: Est min | J4: Status | K4: Priority | L4: Order | M4: Notes / source caveats
A5: Paper I | B5: Neuroradiology | C5: Brain - neoplastic | D5: Intracranial tumours - supra & infratentorial | E5: 8 | F5: ★ | G5: 30 | H5: Very High | I5: 40 | J5: Not Started | L5: =(IF(J5="Partial",1,IF(J5="Not Started",2,IF(J5="Covered",3,2))))*10+(IF(K5="High",1,IF(K5="Medium",2,IF(K5="Low",3,2)))) -> 22
A6: Paper I | B6: Neuroradiology | C6: Brain - neoplastic | D6: Pituitary & sellar region masses | E6: 9 | F6: ★ | G6: 30 | H6: Very High | I6: 30 | J6: Not Started | L6: =(IF(J6="Partial",1,IF(J6="Not Started",2,IF(J6="Covered",3,2))))*10+(IF(K6="High",1,IF(K6="Medium",2,IF(K6="Low",3,2)))) -> 22
A7: Paper I | B7: Neuroradiology | C7: Brain - vascular | D7: Ischaemic stroke - CT/MRI & penumbra | E7: 9 | F7: ★ | G7: 30 | H7: Very High | I7: 35 | J7: Not Started | L7: =(IF(J7="Partial",1,IF(J7="Not Started",2,IF(J7="Covered",3,2))))*10+(IF(K7="High",1,IF(K7="Medium",2,IF(K7="Low",3,2)))) -> 22 | M7: Also tested in Paper II/IV (acute & IR).
A8: Paper I | B8: Neuroradiology | C8: Brain - vascular | D8: Intracranial haemorrhage & aneurysm/AVM | E8: 9 | F8: ★ | G8: 30 | H8: Very High | I8: 35 | J8: Not Started | L8: =(IF(J8="Partial",1,IF(J8="Not Started",2,IF(J8="Covered",3,2))))*10+(IF(K8="High",1,IF(K8="Medium",2,IF(K8="Low",3,2)))) -> 22
A9: Paper I | B9: Neuroradiology | C9: Brain - infective/inflammatory | D9: CNS infections (TB, NCC, pyogenic, fungal) | E9: 9 | F9: ★ | G9: 30 | H9: Very High | I9: 35 | J9: Not Started | L9: =(IF(J9="Partial",1,IF(J9="Not Started",2,IF(J9="Covered",3,2))))*10+(IF(K9="High",1,IF(K9="Medium",2,IF(K9="Low",3,2)))) -> 22
A10: Paper I | B10: Neuroradiology | C10: Brain - infective/inflammatory | D10: Demyelinating & degenerative disorders | E10: 9 | G10: 30 | H10: Very High | I10: 30 | J10: Not Started | L10: =(IF(J10="Partial",1,IF(J10="Not Started",2,IF(J10="Covered",3,2))))*10+(IF(K10="High",1,IF(K10="Medium",2,IF(K10="Low",3,2)))) -> 22
A11: Paper I | B11: Neuroradiology | C11: Brain - infective/inflammatory | D11: CNS in HIV & congenital TORCH | E11: 9 | G11: 30 | H11: Very High | I11: 25 | J11: Not Started | L11: =(IF(J11="Partial",1,IF(J11="Not Started",2,IF(J11="Covered",3,2))))*10+(IF(K11="High",1,IF(K11="Medium",2,IF(K11="Low",3,2)))) -> 22
A12: Paper I | B12: Neuroradiology | C12: Phakomatoses | D12: Neurocutaneous syndromes (NF, Sturge-Weber, TS) | E12: 9 | F12: ★ | G12: 30 | H12: Very High | I12: 25 | J12: Not Started | L12: =(IF(J12="Partial",1,IF(J12="Not Started",2,IF(J12="Covered",3,2))))*10+(IF(K12="High",1,IF(K12="Medium",2,IF(K12="Low",3,2)))) -> 22
A13: Paper I | B13: Neuroradiology | C13: Spine | D13: Spine - approach, cord & canal tumours, myelopathy | E13: 7 | F13: ★ | G13: 30 | H13: Very High | I13: 35 | J13: Not Started | L13: =(IF(J13="Partial",1,IF(J13="Not Started",2,IF(J13="Covered",3,2))))*10+(IF(K13="High",1,IF(K13="Medium",2,IF(K13="Low",3,2)))) -> 22
A14: Paper I | B14: Neuroradiology | C14: Methods | D14: CNS imaging methods, perfusion, spectroscopy | E14: 5 | G14: 30 | H14: Very High | I14: 25 | J14: Not Started | L14: =(IF(J14="Partial",1,IF(J14="Not Started",2,IF(J14="Covered",3,2))))*10+(IF(K14="High",1,IF(K14="Medium",2,IF(K14="Low",3,2)))) -> 22
A15: Paper I | B15: Head & Neck | C15: Orbit | D15: Orbit - intraocular, orbital masses, exophthalmos, trauma | E15: 9 | F15: ★ | G15: 23 | H15: High | I15: 30 | J15: Not Started | L15: =(IF(J15="Partial",1,IF(J15="Not Started",2,IF(J15="Covered",3,2))))*10+(IF(K15="High",1,IF(K15="Medium",2,IF(K15="Low",3,2)))) -> 22
A16: Paper I | B16: Head & Neck | C16: Sinonasal | D16: Nose & paranasal sinuses | E16: 5 | G16: 23 | H16: High | I16: 25 | J16: Not Started | L16: =(IF(J16="Partial",1,IF(J16="Not Started",2,IF(J16="Covered",3,2))))*10+(IF(K16="High",1,IF(K16="Medium",2,IF(K16="Low",3,2)))) -> 22
A17: Paper I | B17: Head & Neck | C17: Temporal bone | D17: Ear / temporal bone HRCT & inner ear MRI | E17: 5 | F17: ★ | G17: 23 | H17: High | I17: 30 | J17: Not Started | L17: =(IF(J17="Partial",1,IF(J17="Not Started",2,IF(J17="Covered",3,2))))*10+(IF(K17="High",1,IF(K17="Medium",2,IF(K17="Low",3,2)))) -> 22
A18: Paper I | B18: Head & Neck | C18: Neck spaces | D18: Neck spaces anatomy & disease spread; nodal levels | E18: 5 | F18: ★ | G18: 23 | H18: High | I18: 30 | J18: Not Started | L18: =(IF(J18="Partial",1,IF(J18="Not Started",2,IF(J18="Covered",3,2))))*10+(IF(K18="High",1,IF(K18="Medium",2,IF(K18="Low",3,2)))) -> 22
A19: Paper I | B19: Head & Neck | C19: Neck spaces | D19: Larynx, pharynx & H&N malignancy staging | E19: 5 | F19: ★ | G19: 23 | H19: High | I19: 30 | J19: Not Started | L19: =(IF(J19="Partial",1,IF(J19="Not Started",2,IF(J19="Covered",3,2))))*10+(IF(K19="High",1,IF(K19="Medium",2,IF(K19="Low",3,2)))) -> 22
A20: Paper I | B20: Head & Neck | C20: Congenital neck | D20: Congenital neck masses (thyroglossal, branchial) | E20: 8 | F20: ★ | G20: 23 | H20: High | I20: 25 | J20: Not Started | L20: =(IF(J20="Partial",1,IF(J20="Not Started",2,IF(J20="Covered",3,2))))*10+(IF(K20="High",1,IF(K20="Medium",2,IF(K20="Low",3,2)))) -> 22
A21: Paper I | B21: Head & Neck | C21: Maxillofacial/dental | D21: Maxillofacial, dental, TMJ & salivary glands | E21: 5 | G21: 23 | H21: High | I21: 30 | J21: Not Started | L21: =(IF(J21="Partial",1,IF(J21="Not Started",2,IF(J21="Covered",3,2))))*10+(IF(K21="High",1,IF(K21="Medium",2,IF(K21="Low",3,2)))) -> 22
A22: Paper I | B22: Endocrine | C22: Thyroid | D22: Thyroid & parathyroid imaging (nodule US, TIRADS) | E22: 9 | F22: ★ | G22: 7 | H22: Lower | I22: 25 | J22: Not Started | L22: =(IF(J22="Partial",1,IF(J22="Not Started",2,IF(J22="Covered",3,2))))*10+(IF(K22="High",1,IF(K22="Medium",2,IF(K22="Low",3,2)))) -> 22
A23: Paper I | B23: Endocrine | C23: Adrenal | D23: Adrenal imaging | E23: Not aplicable | G23: 7 | H23: Lower | I23: 20 | J23: Not Started | L23: =(IF(J23="Partial",1,IF(J23="Not Started",2,IF(J23="Covered",3,2))))*10+(IF(K23="High",1,IF(K23="Medium",2,IF(K23="Low",3,2)))) -> 22
A24: Paper I | B24: Endocrine | C24: Other | D24: Pituitary/pancreatic/gonadal endocrine imaging | E24: Not aplicable | G24: 7 | H24: Lower | I24: 15 | J24: Not Started | L24: =(IF(J24="Partial",1,IF(J24="Not Started",2,IF(J24="Covered",3,2))))*10+(IF(K24="High",1,IF(K24="Medium",2,IF(K24="Low",3,2)))) -> 22
A25: Paper I | B25: Musculoskeletal | C25: Trauma | D25: Skeletal trauma - spine, pelvis, appendicular | E25: 3 | F25: ★ | G25: 33 | H25: Very High | I25: 35 | J25: Not Started | L25: =(IF(J25="Partial",1,IF(J25="Not Started",2,IF(J25="Covered",3,2))))*10+(IF(K25="High",1,IF(K25="Medium",2,IF(K25="Low",3,2)))) -> 22
A26: Paper I | B26: Musculoskeletal | C26: Tumours | D26: Bone tumours - benign, malignant, metastases | E26: 3 | F26: ★ | G26: 33 | H26: Very High | I26: 40 | J26: Not Started | L26: =(IF(J26="Partial",1,IF(J26="Not Started",2,IF(J26="Covered",3,2))))*10+(IF(K26="High",1,IF(K26="Medium",2,IF(K26="Low",3,2)))) -> 22
A27: Paper I | B27: Musculoskeletal | C27: Tumours | D27: Bone-forming & cartilage tumours (osteosarcoma, Ewing) | E27: 3 | F27: ★ | G27: 33 | H27: Very High | I27: 30 | J27: Not Started | L27: =(IF(J27="Partial",1,IF(J27="Not Started",2,IF(J27="Covered",3,2))))*10+(IF(K27="High",1,IF(K27="Medium",2,IF(K27="Low",3,2)))) -> 22
A28: Paper I | B28: Musculoskeletal | C28: Infection | D28: Osteomyelitis & septic/granulomatous arthritis | E28: 3 | F28: ★ | G28: 33 | H28: Very High | I28: 30 | J28: Not Started | L28: =(IF(J28="Partial",1,IF(J28="Not Started",2,IF(J28="Covered",3,2))))*10+(IF(K28="High",1,IF(K28="Medium",2,IF(K28="Low",3,2)))) -> 22
A29: Paper I | B29: Musculoskeletal | C29: Metabolic | D29: Metabolic bone disease, rickets, bone density | E29: 3 | F29: ★ | G29: 33 | H29: Very High | I29: 30 | J29: Not Started | L29: =(IF(J29="Partial",1,IF(J29="Not Started",2,IF(J29="Covered",3,2))))*10+(IF(K29="High",1,IF(K29="Medium",2,IF(K29="Low",3,2)))) -> 22
A30: Paper I | B30: Musculoskeletal | C30: Dysplasia | D30: Skeletal dysplasias & paediatric MSK | E30: 3 | G30: 33 | H30: Very High | I30: 25 | J30: Not Started | L30: =(IF(J30="Partial",1,IF(J30="Not Started",2,IF(J30="Covered",3,2))))*10+(IF(K30="High",1,IF(K30="Medium",2,IF(K30="Low",3,2)))) -> 22
A31: Paper I | B31: Musculoskeletal | C31: Arthropathy | D31: Arthropathies (inflammatory, crystal, degenerative) | E31: 3 | F31: ★ | G31: 33 | H31: Very High | I31: 30 | J31: Not Started | L31: =(IF(J31="Partial",1,IF(J31="Not Started",2,IF(J31="Covered",3,2))))*10+(IF(K31="High",1,IF(K31="Medium",2,IF(K31="Low",3,2)))) -> 22
A32: Paper I | B32: Musculoskeletal | C32: Cross-sectional | D32: MSK MRI - internal derangement, marrow, joints | E32: 3 | F32: ★ | G32: 33 | H32: Very High | I32: 35 | J32: Not Started | L32: =(IF(J32="Partial",1,IF(J32="Not Started",2,IF(J32="Covered",3,2))))*10+(IF(K32="High",1,IF(K32="Medium",2,IF(K32="Low",3,2)))) -> 22
A33: Paper I | B33: Musculoskeletal | C33: Cross-sectional | D33: MSK ultrasound & soft-tissue/nerve sheath lesions | E33: 3 | G33: 33 | H33: Very High | I33: 25 | J33: Not Started | L33: =(IF(J33="Partial",1,IF(J33="Not Started",2,IF(J33="Covered",3,2))))*10+(IF(K33="High",1,IF(K33="Medium",2,IF(K33="Low",3,2)))) -> 22
A34: Paper I | B34: Musculoskeletal | C34: Haematological | D34: Skeletal changes in leukaemia/haemolytic anaemia | E34: 3 | G34: 33 | H34: Very High | I34: 20 | J34: Not Started | L34: =(IF(J34="Partial",1,IF(J34="Not Started",2,IF(J34="Covered",3,2))))*10+(IF(K34="High",1,IF(K34="Medium",2,IF(K34="Low",3,2)))) -> 22
A35: Paper I | B35: Breast | C35: Diagnostic | D35: Mammography/US/MRI, benign vs malignant, BI-RADS | E35: 9 | F35: ★ | G35: 7 | H35: Lower | I35: 30 | J35: Not Started | L35: =(IF(J35="Partial",1,IF(J35="Not Started",2,IF(J35="Covered",3,2))))*10+(IF(K35="High",1,IF(K35="Medium",2,IF(K35="Low",3,2)))) -> 22 | M35: Paper varies: women's imaging (III) vs soft tissue (I). Appears in Paper I in sample.
A36: Paper I | B36: Breast | C36: Screening/IR | D36: Breast screening, tomosynthesis & intervention | E36: 9 | G36: 7 | H36: Lower | I36: 20 | J36: Not Started | L36: =(IF(J36="Partial",1,IF(J36="Not Started",2,IF(J36="Covered",3,2))))*10+(IF(K36="High",1,IF(K36="Medium",2,IF(K36="Low",3,2)))) -> 22
A37: Paper II | B37: Pulmonary / Chest | C37: Normal/technique | D37: Normal chest, CXR views, systematic interpretation | E37: Not aplicable | F37: ★ | G37: 48 | H37: Very High | I37: 30 | J37: Not Started | L37: =(IF(J37="Partial",1,IF(J37="Not Started",2,IF(J37="Covered",3,2))))*10+(IF(K37="High",1,IF(K37="Medium",2,IF(K37="Low",3,2)))) -> 22
A38: Paper II | B38: Pulmonary / Chest | C38: Mediastinum/pleura | D38: Mediastinum (incl. posterior masses), pleura, diaphragm | E38: 9 | F38: ★ | G38: 48 | H38: Very High | I38: 35 | J38: Not Started | L38: =(IF(J38="Partial",1,IF(J38="Not Started",2,IF(J38="Covered",3,2))))*10+(IF(K38="High",1,IF(K38="Medium",2,IF(K38="Low",3,2)))) -> 22
A39: Paper II | B39: Pulmonary / Chest | C39: Airways/airspace | D39: Airways disease, collapse & consolidation | F39: ★ | G39: 48 | H39: Very High | I39: 30 | J39: Not Started | L39: =(IF(J39="Partial",1,IF(J39="Not Started",2,IF(J39="Covered",3,2))))*10+(IF(K39="High",1,IF(K39="Medium",2,IF(K39="Low",3,2)))) -> 22
A40: Paper II | B40: Pulmonary / Chest | C40: Infection | D40: Pulmonary infections (incl. TB, hydatid, COVID) | F40: ★ | G40: 48 | H40: Very High | I40: 35 | J40: Not Started | L40: =(IF(J40="Partial",1,IF(J40="Not Started",2,IF(J40="Covered",3,2))))*10+(IF(K40="High",1,IF(K40="Medium",2,IF(K40="Low",3,2)))) -> 22
A41: Paper II | B41: Pulmonary / Chest | C41: Neoplasm | D41: Pulmonary neoplasms & solitary/multiple nodules | F41: ★ | G41: 48 | H41: Very High | I41: 35 | J41: Not Started | L41: =(IF(J41="Partial",1,IF(J41="Not Started",2,IF(J41="Covered",3,2))))*10+(IF(K41="High",1,IF(K41="Medium",2,IF(K41="Low",3,2)))) -> 22
...

Sheet Dashboard
A1: Revision Dashboard - by Category
A2: Counts update as you set Status. 'Marks/session' is frequency-based (see Sources).
A4: Paper | B4: Category | C4: Marks/ session | D4: Tier | E4: Topics | F4: Covered | G4: Partial | H4: Not Started | I4: % done (incl. partial)
A5: Paper I | B5: Musculoskeletal | C5: 33 | D5: Very High | E5: =COUNTIF(Tracker!$B$5:$B$106,B5) -> 10 | F5: =COUNTIFS(Tracker!$B$5:$B$106,B5,Tracker!$J$5:$J$106,"Covered") -> 0 | G5: =COUNTIFS(Tracker!$B$5:$B$106,B5,Tracker!$J$5:$J$106,"Partial") -> 0 | H5: =COUNTIFS(Tracker!$B$5:$B$106,B5,Tracker!$J$5:$J$106,"Not Started") -> 10 | I5: =IF(E5=0,0,(F5+0.5*G5)/E5) -> 0
A6: Paper I | B6: Neuroradiology | C6: 30 | D6: Very High | E6: =COUNTIF(Tracker!$B$5:$B$106,B6) -> 10 | F6: =COUNTIFS(Tracker!$B$5:$B$106,B6,Tracker!$J$5:$J$106,"Covered") -> 0 | G6: =COUNTIFS(Tracker!$B$5:$B$106,B6,Tracker!$J$5:$J$106,"Partial") -> 0 | H6: =COUNTIFS(Tracker!$B$5:$B$106,B6,Tracker!$J$5:$J$106,"Not Started") -> 10 | I6: =IF(E6=0,0,(F6+0.5*G6)/E6) -> 0
A7: Paper I | B7: Head & Neck | C7: 23 | D7: High | E7: =COUNTIF(Tracker!$B$5:$B$106,B7) -> 7 | F7: =COUNTIFS(Tracker!$B$5:$B$106,B7,Tracker!$J$5:$J$106,"Covered") -> 0 | G7: =COUNTIFS(Tracker!$B$5:$B$106,B7,Tracker!$J$5:$J$106,"Partial") -> 0 | H7: =COUNTIFS(Tracker!$B$5:$B$106,B7,Tracker!$J$5:$J$106,"Not Started") -> 7 | I7: =IF(E7=0,0,(F7+0.5*G7)/E7) -> 0
A8: Paper I | B8: Endocrine | C8: 7 | D8: Lower | E8: =COUNTIF(Tracker!$B$5:$B$106,B8) -> 3 | F8: =COUNTIFS(Tracker!$B$5:$B$106,B8,Tracker!$J$5:$J$106,"Covered") -> 0 | G8: =COUNTIFS(Tracker!$B$5:$B$106,B8,Tracker!$J$5:$J$106,"Partial") -> 0 | H8: =COUNTIFS(Tracker!$B$5:$B$106,B8,Tracker!$J$5:$J$106,"Not Started") -> 3 | I8: =IF(E8=0,0,(F8+0.5*G8)/E8) -> 0
A9: Paper I | B9: Breast | C9: 7 | D9: Lower | E9: =COUNTIF(Tracker!$B$5:$B$106,B9) -> 2 | F9: =COUNTIFS(Tracker!$B$5:$B$106,B9,Tracker!$J$5:$J$106,"Covered") -> 0 | G9: =COUNTIFS(Tracker!$B$5:$B$106,B9,Tracker!$J$5:$J$106,"Partial") -> 0 | H9: =COUNTIFS(Tracker!$B$5:$B$106,B9,Tracker!$J$5:$J$106,"Not Started") -> 2 | I9: =IF(E9=0,0,(F9+0.5*G9)/E9) -> 0
A10: Paper II | B10: Pulmonary / Chest | C10: 48 | D10: Very High | E10: =COUNTIF(Tracker!$B$5:$B$106,B10) -> 10 | F10: =COUNTIFS(Tracker!$B$5:$B$106,B10,Tracker!$J$5:$J$106,"Covered") -> 0 | G10: =COUNTIFS(Tracker!$B$5:$B$106,B10,Tracker!$J$5:$J$106,"Partial") -> 0 | H10: =COUNTIFS(Tracker!$B$5:$B$106,B10,Tracker!$J$5:$J$106,"Not Started") -> 10 | I10: =IF(E10=0,0,(F10+0.5*G10)/E10) -> 0
A11: Paper II | B11: Vascular & Doppler | C11: 20 | D11: High | E11: =COUNTIF(Tracker!$B$5:$B$106,B11) -> 4 | F11: =COUNTIFS(Tracker!$B$5:$B$106,B11,Tracker!$J$5:$J$106,"Covered") -> 0 | G11: =COUNTIFS(Tracker!$B$5:$B$106,B11,Tracker!$J$5:$J$106,"Partial") -> 0 | H11: =COUNTIFS(Tracker!$B$5:$B$106,B11,Tracker!$J$5:$J$106,"Not Started") -> 4 | I11: =IF(E11=0,0,(F11+0.5*G11)/E11) -> 0
A12: Paper II | B12: Cardiovascular | C12: 18 | D12: High | E12: =COUNTIF(Tracker!$B$5:$B$106,B12) -> 6 | F12: =COUNTIFS(Tracker!$B$5:$B$106,B12,Tracker!$J$5:$J$106,"Covered") -> 0 | G12: =COUNTIFS(Tracker!$B$5:$B$106,B12,Tracker!$J$5:$J$106,"Partial") -> 0 | H12: =COUNTIFS(Tracker!$B$5:$B$106,B12,Tracker!$J$5:$J$106,"Not Started") -> 6 | I12: =IF(E12=0,0,(F12+0.5*G12)/E12) -> 0
A13: Paper II | B13: Emergency & Trauma | C13: 13 | D13: Moderate | E13: =COUNTIF(Tracker!$B$5:$B$106,B13) -> 3 | F13: =COUNTIFS(Tracker!$B$5:$B$106,B13,Tracker!$J$5:$J$106,"Covered") -> 0 | G13: =COUNTIFS(Tracker!$B$5:$B$106,B13,Tracker!$J$5:$J$106,"Partial") -> 0 | H13: =COUNTIFS(Tracker!$B$5:$B$106,B13,Tracker!$J$5:$J$106,"Not Started") -> 3 | I13: =IF(E13=0,0,(F13+0.5*G13)/E13) -> 0
A14: Paper III | B14: GI & Hepatobiliary | C14: 43 | D14: Very High | E14: =COUNTIF(Tracker!$B$5:$B$106,B14) -> 10 | F14: =COUNTIFS(Tracker!$B$5:$B$106,B14,Tracker!$J$5:$J$106,"Covered") -> 0 | G14: =COUNTIFS(Tracker!$B$5:$B$106,B14,Tracker!$J$5:$J$106,"Partial") -> 0 | H14: =COUNTIFS(Tracker!$B$5:$B$106,B14,Tracker!$J$5:$J$106,"Not Started") -> 10 | I14: =IF(E14=0,0,(F14+0.5*G14)/E14) -> 0
A15: Paper III | B15: Genitourinary | C15: 30 | D15: Very High | E15: =COUNTIF(Tracker!$B$5:$B$106,B15) -> 9 | F15: =COUNTIFS(Tracker!$B$5:$B$106,B15,Tracker!$J$5:$J$106,"Covered") -> 0 | G15: =COUNTIFS(Tracker!$B$5:$B$106,B15,Tracker!$J$5:$J$106,"Partial") -> 0 | H15: =COUNTIFS(Tracker!$B$5:$B$106,B15,Tracker!$J$5:$J$106,"Not Started") -> 9 | I15: =IF(E15=0,0,(F15+0.5*G15)/E15) -> 0
A16: Paper III | B16: Obstetrics | C16: 15 | D16: Moderate | E16: =COUNTIF(Tracker!$B$5:$B$106,B16) -> 4 | F16: =COUNTIFS(Tracker!$B$5:$B$106,B16,Tracker!$J$5:$J$106,"Covered") -> 0 | G16: =COUNTIFS(Tracker!$B$5:$B$106,B16,Tracker!$J$5:$J$106,"Partial") -> 0 | H16: =COUNTIFS(Tracker!$B$5:$B$106,B16,Tracker!$J$5:$J$106,"Not Started") -> 4 | I16: =IF(E16=0,0,(F16+0.5*G16)/E16) -> 0
... A23: Paper IV | B23: Nuclear Medicine | C23: 5 | D23: Lower | E23: =COUNTIF(Tracker!$B$5:$B$106,B23) -> 2 | F23: =COUNTIFS(Tracker!$B$5:$B$106,B23,Tracker!$J$5:$J$106,"Covered") -> 0 | G23: =COUNTIFS(Tracker!$B$5:$B$106,B23,Tracker!$J$5:$J$106,"Partial") -> 0 | H23: =COUNTIFS(Tracker!$B$5:$B$106,B23,Tracker!$J$5:$J$106,"Not Started") -> 2 | I23: =IF(E23=0,0,(F23+0.5*G23)/E23) -> 0

Sheet Sources & Method
A1: Sources, Marks & Weighting Method
A3: OFFICIAL (sourced) exam structure
A4: 4 papers x 100 marks = 400. Each paper: 10 short-note questions x 10 marks, 3 hours. Parts A & B (5+5).
A5: Pass: >=200/400 aggregate (broad specialty). Source: NBE DNB Radio Diagnosis curriculum guideline + NBEMS notices.
A6: There is NO official per-topic mark allocation. Topic weighting below is EMPIRICAL (question frequency).
A8: Past papers analysed (each question = 10 marks; confirmed on official NBEMS papers)
A9: Paper I : Dec 2021, Jun 2022, Apr 2023 (3 sessions, 30 questions)
A10: Paper II : Dec 2021, Jun 2022, Oct 2023 (3 sessions, 30 questions)
A11: Paper III: Dec 2021, Jun 2022, Oct 2023 (3 sessions, 30 questions)
A12: Paper IV : Dec 2021, Jun 2022 (2 sessions, 20 questions)
A13: Total: 110 questions / 1100 marks. Sources: official natboard.edu.in question papers (Apr23/Oct23) + radioloksabha (Dec21/Jun22).
A15: How 'Cat marks/session' was derived
... A24: NBE revises guidelines periodically; your information bulletin is the final word.
